To execute the default application inside the container, run:
singularity run --nv $CONTAINERDIR/pytorch-2.0.1.sif

This container is based on NGC 23.08
https://docs.nvidia.com/deeplearning/frameworks/pytorch-release-notes/rel-23-08.html#rel-23-08
WARNING: Ignoring invalid distribution -riton-nightly (/sfs/qumulo/qhome/brc4cb/.conda/envs/falcon_40B/lib/python3.9/site-packages)
ERROR: Could not find a version that satisfies the requirement PIL (from versions: none)
ERROR: No matching distribution found for PIL
WARNING: Ignoring invalid distribution -riton-nightly (/sfs/qumulo/qhome/brc4cb/.conda/envs/falcon_40B/lib/python3.9/site-packages)
WARNING: Ignoring invalid distribution -riton-nightly (/sfs/qumulo/qhome/brc4cb/.conda/envs/falcon_40B/lib/python3.9/site-packages)
Using cache found in /home/brc4cb/.cache/torch/hub/pytorch_vision_v0.10.0
Using cache found in /home/brc4cb/.cache/torch/hub/pytorch_vision_v0.10.0
Traceback (most recent call last):
  File "/sfs/qumulo/qhome/brc4cb/ml3_assignment2/ensemble.py", line 300, in <module>
    train_model(model, optimizer_ft, exp_lr_scheduler, train_loader, valid_loader, criterion, num_epochs = 100)
  File "/sfs/qumulo/qhome/brc4cb/ml3_assignment2/ensemble.py", line 231, in train_model
    preds = model(data_inputs)
  File "/home/brc4cb/.conda/envs/falcon_40B/lib/python3.9/site-packages/torch/nn/modules/module.py", line 1518, in _wrapped_call_impl
    return self._call_impl(*args, **kwargs)
  File "/home/brc4cb/.conda/envs/falcon_40B/lib/python3.9/site-packages/torch/nn/modules/module.py", line 1527, in _call_impl
    return forward_call(*args, **kwargs)
  File "/home/brc4cb/.conda/envs/falcon_40B/lib/python3.9/site-packages/torch/nn/parallel/data_parallel.py", line 185, in forward
    outputs = self.parallel_apply(replicas, inputs, module_kwargs)
  File "/home/brc4cb/.conda/envs/falcon_40B/lib/python3.9/site-packages/torch/nn/parallel/data_parallel.py", line 200, in parallel_apply
    return parallel_apply(replicas, inputs, kwargs, self.device_ids[:len(replicas)])
  File "/home/brc4cb/.conda/envs/falcon_40B/lib/python3.9/site-packages/torch/nn/parallel/parallel_apply.py", line 110, in parallel_apply
    output.reraise()
  File "/home/brc4cb/.conda/envs/falcon_40B/lib/python3.9/site-packages/torch/_utils.py", line 694, in reraise
    raise exception
RuntimeError: Caught RuntimeError in replica 0 on device 0.
Original Traceback (most recent call last):
  File "/home/brc4cb/.conda/envs/falcon_40B/lib/python3.9/site-packages/torch/nn/parallel/parallel_apply.py", line 85, in _worker
    output = module(*input, **kwargs)
  File "/home/brc4cb/.conda/envs/falcon_40B/lib/python3.9/site-packages/torch/nn/modules/module.py", line 1518, in _wrapped_call_impl
    return self._call_impl(*args, **kwargs)
  File "/home/brc4cb/.conda/envs/falcon_40B/lib/python3.9/site-packages/torch/nn/modules/module.py", line 1527, in _call_impl
    return forward_call(*args, **kwargs)
  File "/sfs/qumulo/qhome/brc4cb/ml3_assignment2/ensemble.py", line 203, in forward
    out1 = self.modelA(x)
  File "/home/brc4cb/.conda/envs/falcon_40B/lib/python3.9/site-packages/torch/nn/modules/module.py", line 1518, in _wrapped_call_impl
    return self._call_impl(*args, **kwargs)
  File "/home/brc4cb/.conda/envs/falcon_40B/lib/python3.9/site-packages/torch/nn/modules/module.py", line 1527, in _call_impl
    return forward_call(*args, **kwargs)
  File "/home/brc4cb/.conda/envs/falcon_40B/lib/python3.9/site-packages/torch/nn/parallel/data_parallel.py", line 185, in forward
    outputs = self.parallel_apply(replicas, inputs, module_kwargs)
  File "/home/brc4cb/.conda/envs/falcon_40B/lib/python3.9/site-packages/torch/nn/parallel/data_parallel.py", line 200, in parallel_apply
    return parallel_apply(replicas, inputs, kwargs, self.device_ids[:len(replicas)])
  File "/home/brc4cb/.conda/envs/falcon_40B/lib/python3.9/site-packages/torch/nn/parallel/parallel_apply.py", line 110, in parallel_apply
    output.reraise()
  File "/home/brc4cb/.conda/envs/falcon_40B/lib/python3.9/site-packages/torch/_utils.py", line 694, in reraise
    raise exception
RuntimeError: Caught RuntimeError in replica 1 on device 1.
Original Traceback (most recent call last):
  File "/home/brc4cb/.conda/envs/falcon_40B/lib/python3.9/site-packages/torch/nn/parallel/parallel_apply.py", line 85, in _worker
    output = module(*input, **kwargs)
  File "/home/brc4cb/.conda/envs/falcon_40B/lib/python3.9/site-packages/torch/nn/modules/module.py", line 1518, in _wrapped_call_impl
    return self._call_impl(*args, **kwargs)
  File "/home/brc4cb/.conda/envs/falcon_40B/lib/python3.9/site-packages/torch/nn/modules/module.py", line 1527, in _call_impl
    return forward_call(*args, **kwargs)
  File "/home/brc4cb/.conda/envs/falcon_40B/lib/python3.9/site-packages/torchvision/models/resnet.py", line 285, in forward
    return self._forward_impl(x)
  File "/home/brc4cb/.conda/envs/falcon_40B/lib/python3.9/site-packages/torchvision/models/resnet.py", line 268, in _forward_impl
    x = self.conv1(x)
  File "/home/brc4cb/.conda/envs/falcon_40B/lib/python3.9/site-packages/torch/nn/modules/module.py", line 1518, in _wrapped_call_impl
    return self._call_impl(*args, **kwargs)
  File "/home/brc4cb/.conda/envs/falcon_40B/lib/python3.9/site-packages/torch/nn/modules/module.py", line 1527, in _call_impl
    return forward_call(*args, **kwargs)
  File "/home/brc4cb/.conda/envs/falcon_40B/lib/python3.9/site-packages/torch/nn/modules/conv.py", line 460, in forward
    return self._conv_forward(input, self.weight, self.bias)
  File "/home/brc4cb/.conda/envs/falcon_40B/lib/python3.9/site-packages/torch/nn/modules/conv.py", line 456, in _conv_forward
    return F.conv2d(input, weight, bias, self.stride,
RuntimeError: Expected all tensors to be on the same device, but found at least two devices, cuda:1 and cuda:0! (when checking argument for argument weight in method wrapper_CUDA__cudnn_convolution)


